<?xml version="1.0"?>
<robot xmlns:xacro="http://www.ros.org/wiki/xacro">

    <xacro:include filename="inertial_macros.xacro"/>

    <!-- creating a global color graphs -->
    <material name="white">
        <color rgba="1 1 1 1"/>
    </material>

    <material name="black">
        <color rgba="0 0 0 1"/>
    </material>

    <material name="grey">
        <color rgba="0.5 0.5 0.5 1"/>   
    </material>

    <material name = "blue">
        <color rgba="0.2 0.2 1 1"/>
    </material>

    <material name = "orange">
        <color rgba = "1 0.3 0.1 1"/>
    </material>


    <!-- first link is called as base link -->
    <link name = "base link">
    </link>

    <!-- chassis (box with some dimentions) -->
    <joint name = "chassis_joint" type = "fixed">
        <parent link = "base link"/>
        <child link = "chassis"/>
        <origin xyz = "-0.1 0 0"/>
    </joint>

    <link name = "chassis">
        <visual>
            <origin xyz = "0.2 0 0.1" />
            <geometry>
                <box size = "0.4 0.3 0.2"/>
            </geometry>
            <material name = "grey"/>
        </visual>

        <collision>
            <origin xyz = "0.2 0 0.1" />
            <geometry>
                <box size = "0.4 0.3 0.2"/>
            </geometry>
        </collision>   

        <xacro:inertial_box mass = "0.5" x="0.4" y="0.3" z="0.2">
            <origin xyz="0.2 0 0.1" rpy="0 0 0"/>
        </xacro:inertial_box>
    </link>

    <!-- Left wheel -->
    <joint name = "left_wheel_joint" type = "continuous">
        <parent link = "base link"/>
        <child link = "left wheel"/>
        <origin xyz = "0 0.175 0" rpy ="-${pi/2} 0 0"/>
        <axis xyz = "0 0 1"/>
    </joint>

    <link name = "left wheel">
        <visual>
            <geometry>
                <cylinder radius = "0.1" length = "0.05" />
            </geometry>
            <material name = "blue"/>
        </visual>

        <collision>
            <geometry>
                <cylinder radius = "0.1" length = "0.05" />
            </geometry>
        </collision>

        <xacro:inertial_cylinder mass="0.2" length="0.05" radius="0.1">
            <origin xyz = "0 0 0" rpy="0 0 0"/>
        </xacro:inertial_cylinder>

    </link>

    <!-- Right wheel -->
    <joint name = "right_wheel_joint" type = "continuous">
        <parent link = "base link"/>
        <child link = "right wheel"/>
        <origin xyz = "0 -0.175 0" rpy ="${pi/2} 0 0"/>
        <axis xyz = "0 0 -1"/>
    </joint>

    <link name = "right wheel">
        <visual>
            <geometry>
                <cylinder radius = "0.1" length = "0.05" />
            </geometry>
            <material name = "blue"/>
        </visual>

        <collision>
            <geometry>
                <cylinder radius="0.1" length="0.05" />
            </geometry>
        </collision>

        <xacro:inertial_cylinder mass="0.2" length="0.05" radius="0.1">
            <origin xyz="0 0 0" rpy="0 0 0"/>
        </xacro:inertial_cylinder>

    </link>

    <!-- chaster wheel (that bulb like thing) -->
    <joint name = "chaster_wheel_joint" type = "fixed">
        <parent link = "base link"/>
        <child link = "chaster wheel"/>
        <origin xyz = "0.2 0 0" rpy ="0 0 0"/>
    </joint>

    <link name = "chaster wheel">
        <visual>
            <geometry>
                <sphere radius = "0.05"/>
            </geometry>
            <material name = "orange"/>
        </visual>

        <collision>
            <geometry>
                <sphere radius = "0.05"/>
            </geometry>
        </collision>  

        <xacro:inertial_sphere mass="0.2" radius="0.05">
            <origin xyz="0 0 0" rpy="0 0 0" />
        </xacro:inertial_sphere>

    </link>

    <xacro />
</robot>